Workbook

Sheet Dashboard
A1: Dashboard
A2: Ringkasan keuangan usaha, pribadi, dan proyek — semua dihitung otomatis dari sheet lain.
A3: Saldo Kas Perusahaan | B3: Saldo Kas Pribadi | C3: Total Margin Proyek | D3: Piutang Belum Diterima | F3: Kategori | G3: Nilai
A4: =KU_SaldoAkhir -> 135555000 | B4: =KP_SaldoAkhir -> 3500000 | C4: =MP_TotalMargin -> 40500000 | D4: =KU_Piutang -> 78026000 | F4: Usaha - Masuk | G4: =KU_Pemasukan -> 135555000
F5: Usaha - Keluar | G5: =KU_Pengeluaran -> 0
F6: Pribadi - Masuk | G6: =KP_Pemasukan -> 6000000
F7: Pribadi - Keluar | G7: =KP_Pengeluaran -> 2500000
A20: Transaksi Terbaru
A21: Tanggal | B21: Sumber | C21: Keterangan | D21: Tipe | E21: Jumlah
A22: =IFERROR(INDEX(All_Transaksi!$A$2:$A$181,MATCH(1,All_Transaksi!$G$2:$G$181,0)),"") -> 46241 | B22: =IFERROR(INDEX(All_Transaksi!$B$2:$B$181,MATCH(1,All_Transaksi!$G$2:$G$181,0)),"") -> Kas Perusahaan | C22: =IFERROR(INDEX(All_Transaksi!$C$2:$C$181,MATCH(1,All_Transaksi!$G$2:$G$181,0)),"") -> SPK Tmpk Dpan dan Tiang T NSC Kutoarjo | D22: =IFERROR(INDEX(All_Transaksi!$D$2:$D$181,MATCH(1,All_Transaksi!$G$2:$G$181,0)),"") -> Masuk | E22: =IFERROR(INDEX(All_Transaksi!$E$2:$E$181,MATCH(1,All_Transaksi!$G$2:$G$181,0)),"") -> 4766000
A23: =IFERROR(INDEX(All_Transaksi!$A$2:$A$181,MATCH(2,All_Transaksi!$G$2:$G$181,0)),"") -> 46241 | B23: =IFERROR(INDEX(All_Transaksi!$B$2:$B$181,MATCH(2,All_Transaksi!$G$2:$G$181,0)),"") -> Kas Perusahaan | C23: =IFERROR(INDEX(All_Transaksi!$C$2:$C$181,MATCH(2,All_Transaksi!$G$2:$G$181,0)),"") -> SPK Tmpk Dpan dan Tiang T Gadai Sakti Kutoarjo | D23: =IFERROR(INDEX(All_Transaksi!$D$2:$D$181,MATCH(2,All_Transaksi!$G$2:$G$181,0)),"") -> Masuk | E23: =IFERROR(INDEX(All_Transaksi!$E$2:$E$181,MATCH(2,All_Transaksi!$G$2:$G$181,0)),"") -> 5940000
A24: =IFERROR(INDEX(All_Transaksi!$A$2:$A$181,MATCH(3,All_Transaksi!$G$2:$G$181,0)),"") -> 46240 | B24: =IFERROR(INDEX(All_Transaksi!$B$2:$B$181,MATCH(3,All_Transaksi!$G$2:$G$181,0)),"") -> Kas Perusahaan | C24: =IFERROR(INDEX(All_Transaksi!$C$2:$C$181,MATCH(3,All_Transaksi!$G$2:$G$181,0)),"") -> SPK Gudang Gadai Sakti Sukadami | D24: =IFERROR(INDEX(All_Transaksi!$D$2:$D$181,MATCH(3,All_Transaksi!$G$2:$G$181,0)),"") -> Masuk | E24: =IFERROR(INDEX(All_Transaksi!$E$2:$E$181,MATCH(3,All_Transaksi!$G$2:$G$181,0)),"") -> 9423000
A25: =IFERROR(INDEX(All_Transaksi!$A$2:$A$181,MATCH(4,All_Transaksi!$G$2:$G$181,0)),"") -> 46240 | B25: =IFERROR(INDEX(All_Transaksi!$B$2:$B$181,MATCH(4,All_Transaksi!$G$2:$G$181,0)),"") -> Kas Perusahaan | C25: =IFERROR(INDEX(All_Transaksi!$C$2:$C$181,MATCH(4,All_Transaksi!$G$2:$G$181,0)),"") -> SPK Tampak Depan NSC Kalideres | D25: =IFERROR(INDEX(All_Transaksi!$D$2:$D$181,MATCH(4,All_Transaksi!$G$2:$G$181,0)),"") -> Masuk | E25: =IFERROR(INDEX(All_Transaksi!$E$2:$E$181,MATCH(4,All_Transaksi!$G$2:$G$181,0)),"") -> 4790000
A26: =IFERROR(INDEX(All_Transaksi!$A$2:$A$181,MATCH(5,All_Transaksi!$G$2:$G$181,0)),"") -> 46240 | B26: =IFERROR(INDEX(All_Transaksi!$B$2:$B$181,MATCH(5,All_Transaksi!$G$2:$G$181,0)),"") -> Kas Perusahaan | C26: =IFERROR(INDEX(All_Transaksi!$C$2:$C$181,MATCH(5,All_Transaksi!$G$2:$G$181,0)),"") -> SPK Tampak Depan Gadai Sakti Kalideres | D26: =IFERROR(INDEX(All_Transaksi!$D$2:$D$181,MATCH(5,All_Transaksi!$G$2:$G$181,0)),"") -> Masuk | E26: =IFERROR(INDEX(All_Transaksi!$E$2:$E$181,MATCH(5,All_Transaksi!$G$2:$G$181,0)),"") -> 2626000
A27: =IFERROR(INDEX(All_Transaksi!$A$2:$A$181,MATCH(6,All_Transaksi!$G$2:$G$181,0)),"") -> 46233 | B27: =IFERROR(INDEX(All_Transaksi!$B$2:$B$181,MATCH(6,All_Transaksi!$G$2:$G$181,0)),"") -> Kas Perusahaan | C27: =IFERROR(INDEX(All_Transaksi!$C$2:$C$181,MATCH(6,All_Transaksi!$G$2:$G$181,0)),"") -> BAST Tmpk Dpn dan Tiang T NSC Cipayung | D27: =IFERROR(INDEX(All_Transaksi!$D$2:$D$181,MATCH(6,All_Transaksi!$G$2:$G$181,0)),"") -> Masuk | E27: =IFERROR(INDEX(All_Transaksi!$E$2:$E$181,MATCH(6,All_Transaksi!$G$2:$G$181,0)),"") -> 9685000
A28: =IFERROR(INDEX(All_Transaksi!$A$2:$A$181,MATCH(7,All_Transaksi!$G$2:$G$181,0)),"") -> 46232 | B28: =IFERROR(INDEX(All_Transaksi!$B$2:$B$181,MATCH(7,All_Transaksi!$G$2:$G$181,0)),"") -> Kas Perusahaan | C28: =IFERROR(INDEX(All_Transaksi!$C$2:$C$181,MATCH(7,All_Transaksi!$G$2:$G$181,0)),"") -> BAST Tmpk Dpn dan Tiang T Gadai Sakti Cipayung | D28: =IFERROR(INDEX(All_Transaksi!$D$2:$D$181,MATCH(7,All_Transaksi!$G$2:$G$181,0)),"") -> Masuk | E28: =IFERROR(INDEX(All_Transaksi!$E$2:$E$181,MATCH(7,All_Transaksi!$G$2:$G$181,0)),"") -> 4370000
A29: =IFERROR(INDEX(All_Transaksi!$A$2:$A$181,MATCH(8,All_Transaksi!$G$2:$G$181,0)),"") -> 46231 | B29: =IFERROR(INDEX(All_Transaksi!$B$2:$B$181,MATCH(8,All_Transaksi!$G$2:$G$181,0)),"") -> Kas Perusahaan | C29: =IFERROR(INDEX(All_Transaksi!$C$2:$C$181,MATCH(8,All_Transaksi!$G$2:$G$181,0)),"") -> BAST Tiang T Gadai Sakti Karangmulya | D29: =IFERROR(INDEX(All_Transaksi!$D$2:$D$181,MATCH(8,All_Transaksi!$G$2:$G$181,0)),"") -> Masuk | E29: =IFERROR(INDEX(All_Transaksi!$E$2:$E$181,MATCH(8,All_Transaksi!$G$2:$G$181,0)),"") -> 5000000

Sheet Kas Perusahaan
A1: Kas Perusahaan
A2: Catat semua transaksi kas yang berhubungan dengan usaha. Jangan campur dengan uang pribadi.
B3: Saldo Awal | C3: Total Pemasukan | D3: Total Pengeluaran | E3: Saldo Akhir | F3: Piutang (Belum Diterima)
B4: 0 | C4: =SUMIFS(TblKasUsaha[Jumlah],TblKasUsaha[Tipe],"Masuk",TblKasUsaha[Status],"Lunas") -> 135555000 | D4: =SUMIFS(TblKasUsaha[Jumlah],TblKasUsaha[Tipe],"Keluar") -> 0 | E4: =B4+C4-D4 -> 135555000 | F4: =SUMIFS(TblKasUsaha[Jumlah],TblKasUsaha[Tipe],"Masuk",TblKasUsaha[Status],"Pending") -> 78026000
A7: Tanggal | B7: Keterangan | C7: Kategori | D7: Klien/Proyek | E7: Tipe | F7: Status | G7: Jumlah
A8: 46171 | B8: SPK Tiang T Gadai Sakti Bancar Kembar | C8: Pendapatan Jasa | D8: Gadai Sakti | E8: Masuk | F8: Lunas | G8: 4500000
A9: 46171 | B9: SPK Tiang T Gadai Sakti Karang Lewas | C9: Pendapatan Jasa | D9: Gadai Sakti | E9: Masuk | F9: Lunas | G9: 4500000
A10: 46175 | B10: SPK Tmpk Dpn dan Tiang T Gadai Sakti Jembatan 5 | C10: Pendapatan Jasa | D10: Gadai Sakti | E10: Masuk | F10: Lunas | G10: 8370000
A11: 46177 | B11: SPK CCTV Gadai Sakti Bantul | C11: Pendapatan Jasa | D11: Gadai Sakti | E11: Masuk | F11: Lunas | G11: 4000000
A12: 46182 | B12: SPK Tiang T Gadai Sakti Ngaglik | C12: Pendapatan Jasa | D12: Gadai Sakti | E12: Masuk | F12: Lunas | G12: 2232000
A13: 46182 | B13: SPK Tiang T NSC Ngaglik | C13: Pendapatan Jasa | D13: NSC Finance | E13: Masuk | F13: Lunas | G13: 3019000
A14: 46182 | B14: SPK Tiang T NS Ngaglik | C14: Pendapatan Jasa | D14: Nusantara Sakti | E14: Masuk | F14: Lunas | G14: 3019000
A15: 46183 | B15: BAST Tiang T Gadai Sakti Bancar Kembar | C15: Pendapatan Jasa | D15: Gadai Sakti | E15: Masuk | F15: Lunas | G15: 4500000
A16: 46184 | B16: BAST Tiang T Gadai Sakti Karang Lewas | C16: Pendapatan Jasa | D16: Gadai Sakti | E16: Masuk | F16: Lunas | G16: 4500000
A17: 46186 | B17: SPK Tmpk Dpn dan Tiang T Gadai Sakti Sumberharjo | C17: Pendapatan Jasa | D17: Gadai Sakti | E17: Masuk | F17: Lunas | G17: 7769000
A18: 46186 | B18: SPK CCTV Gadai Sakti Sumberharjo | C18: Pendapatan Jasa | D18: Gadai Sakti | E18: Masuk | F18: Lunas | G18: 5250000
A19: 46190 | B19: SPK Tmpk Dpn dan Tiang T Gadai Sakti Tlogosari | C19: Pendapatan Jasa | D19: Gadai Sakti | E19: Masuk | F19: Lunas | G19: 5388000
... A43: 46241 | B43: SPK Tmpk Dpan dan Tiang T NSC Kutoarjo | C43: Pendapatan Jasa | D43: NSC Finance | E43: Masuk | F43: Pending | G43: 4766000

Sheet Kas Pribadi
A1: Kas Pribadi
A2: Uang pribadi (gaji/prive dari usaha + pengeluaran pribadi). Terpisah total dari Kas Perusahaan.
B3: Saldo Awal | C3: Total Pemasukan | D3: Total Pengeluaran | E3: Saldo Akhir | F3: Prive Bulan Ini
B4: 0 | C4: =SUMIFS(TblKasPribadi[Jumlah],TblKasPribadi[Tipe],"Masuk") -> 6000000 | D4: =SUMIFS(TblKasPribadi[Jumlah],TblKasPribadi[Tipe],"Keluar") -> 2500000 | E4: =B4+C4-D4 -> 3500000 | F4: =SUMPRODUCT((TblKasPribadi[Tipe]="Masuk")*(TblKasPribadi[Kategori]="Prive/Gaji Owner")*(TEXT(TblKasPribadi[Tanggal],"yyyy-mm")=TEXT(TODAY(),"yyyy-mm"))*TblKasPribadi[Jumlah]) -> 0
A7: Tanggal | B7: Keterangan | C7: Kategori | D7: Sumber Dana | E7: Tipe | F7: Jumlah
A8: 46032 | B8: Ambil gaji/prive bulan Januari | C8: Prive/Gaji Owner | D8: Kas Usaha | E8: Masuk | F8: 6000000
A9: 46034 | B9: Kebutuhan rumah tangga | C9: Kebutuhan Harian | D9: - | E9: Keluar | F9: 2500000

Sheet Margin Proyek
A1: Margin per Proyek
A2: Isi data proyek + biaya. Margin & status otomatis terhitung. <15% = Tipis/berisiko, 15-30% = Sehat, >30% = Bagus.
B3: Total Nilai Kontrak | C3: Total Biaya | D3: Total Margin/Laba | E3: Rata-rata Margin
B4: =SUM(B8:B47) -> 105000000 | C4: =SUM(F8:F47) -> 64500000 | D4: =SUM(G8:G47) -> 40500000 | E4: =IF(B4=0,0,D4/B4) -> 0.38571429
A7: Nama Proyek / Klien | B7: Nilai Kontrak | C7: Biaya Bahan | D7: Biaya Upah | E7: Biaya Lain | F7: Total Biaya | G7: Margin | H7: Margin % | I7: Status
A8: Klien A - Signage Toko (Repeat Order Jan) | B8: 45000000 | C8: 14000000 | D8: 9000000 | E8: 2500000 | F8: =IF($A8="","",C8+D8+E8) -> 25500000 | G8: =IF($A8="","",B8-F8) -> 19500000 | H8: =IF($A8="","",IF(B8=0,0,G8/B8)) -> 0.43333333 | I8: =IF($A8="","",IF(H8>0.3,"Bagus",IF(H8>=0.15,"Sehat","Tipis"))) -> Bagus
A9: Klien B - Branding Interior Kantor | B9: 60000000 | C9: 22000000 | D9: 13000000 | E9: 4000000 | F9: =IF($A9="","",C9+D9+E9) -> 39000000 | G9: =IF($A9="","",B9-F9) -> 21000000 | H9: =IF($A9="","",IF(B9=0,0,G9/B9)) -> 0.35 | I9: =IF($A9="","",IF(H9>0.3,"Bagus",IF(H9>=0.15,"Sehat","Tipis"))) -> Bagus
F10: =IF($A10="","",C10+D10+E10) | G10: =IF($A10="","",B10-F10) | H10: =IF($A10="","",IF(B10=0,0,G10/B10)) | I10: =IF($A10="","",IF(H10>0.3,"Bagus",IF(H10>=0.15,"Sehat","Tipis")))
F11: =IF($A11="","",C11+D11+E11) | G11: =IF($A11="","",B11-F11) | H11: =IF($A11="","",IF(B11=0,0,G11/B11)) | I11: =IF($A11="","",IF(H11>0.3,"Bagus",IF(H11>=0.15,"Sehat","Tipis")))
F12: =IF($A12="","",C12+D12+E12) | G12: =IF($A12="","",B12-F12) | H12: =IF($A12="","",IF(B12=0,0,G12/B12)) | I12: =IF($A12="","",IF(H12>0.3,"Bagus",IF(H12>=0.15,"Sehat","Tipis")))
F13: =IF($A13="","",C13+D13+E13) | G13: =IF($A13="","",B13-F13) | H13: =IF($A13="","",IF(B13=0,0,G13/B13)) | I13: =IF($A13="","",IF(H13>0.3,"Bagus",IF(H13>=0.15,"Sehat","Tipis")))
F14: =IF($A14="","",C14+D14+E14) | G14: =IF($A14="","",B14-F14) | H14: =IF($A14="","",IF(B14=0,0,G14/B14)) | I14: =IF($A14="","",IF(H14>0.3,"Bagus",IF(H14>=0.15,"Sehat","Tipis")))
F15: =IF($A15="","",C15+D15+E15) | G15: =IF($A15="","",B15-F15) | H15: =IF($A15="","",IF(B15=0,0,G15/B15)) | I15: =IF($A15="","",IF(H15>0.3,"Bagus",IF(H15>=0.15,"Sehat","Tipis")))
F16: =IF($A16="","",C16+D16+E16) | G16: =IF($A16="","",B16-F16) | H16: =IF($A16="","",IF(B16=0,0,G16/B16)) | I16: =IF($A16="","",IF(H16>0.3,"Bagus",IF(H16>=0.15,"Sehat","Tipis")))
F17: =IF($A17="","",C17+D17+E17) | G17: =IF($A17="","",B17-F17) | H17: =IF($A17="","",IF(B17=0,0,G17/B17)) | I17: =IF($A17="","",IF(H17>0.3,"Bagus",IF(H17>=0.15,"Sehat","Tipis")))
F18: =IF($A18="","",C18+D18+E18) | G18: =IF($A18="","",B18-F18) | H18: =IF($A18="","",IF(B18=0,0,G18/B18)) | I18: =IF($A18="","",IF(H18>0.3,"Bagus",IF(H18>=0.15,"Sehat","Tipis")))
F19: =IF($A19="","",C19+D19+E19) | G19: =IF($A19="","",B19-F19) | H19: =IF($A19="","",IF(B19=0,0,G19/B19)) | I19: =IF($A19="","",IF(H19>0.3,"Bagus",IF(H19>=0.15,"Sehat","Tipis")))
F20: =IF($A20="","",C20+D20+E20) | G20: =IF($A20="","",B20-F20) | H20: =IF($A20="","",IF(B20=0,0,G20/B20)) | I20: =IF($A20="","",IF(H20>0.3,"Bagus",IF(H20>=0.15,"Sehat","Tipis")))
F21: =IF($A21="","",C21+D21+E21) | G21: =IF($A21="","",B21-F21) | H21: =IF($A21="","",IF(B21=0,0,G21/B21)) | I21: =IF($A21="","",IF(H21>0.3,"Bagus",IF(H21>=0.15,"Sehat","Tipis")))
... F47: =IF($A47="","",C47+D47+E47) | G47: =IF($A47="","",B47-F47) | H47: =IF($A47="","",IF(B47=0,0,G47/B47)) | I47: =IF($A47="","",IF(H47>0.3,"Bagus",IF(H47>=0.15,"Sehat","Tipis")))

Sheet Karyawan
A1: Karyawan & Gaji — Daftar Karyawan
A2: Absensi ada di sheet 'Absensi Harian', slip gaji ada di sheet 'Penggajian & Slip Gaji'.
B3: Karyawan Aktif | C3: Total Upah Harian (Aktif) | D3: Total Sisa Pinjaman
B4: =COUNTIF(D8:D37,"Aktif") -> 0 | C4: =SUMIFS(E8:E37,D8:D37,"Aktif") -> 0 | D4: =SUM(L8:L37) -> 0
A7: Nama | B7: Jabatan | C7: Tipe Gaji | D7: Status | E7: Upah Harian | F7: Tarif Lembur/Jam | G7: Uang Makan/Hari | H7: Gaji Bulanan | I7: Target Bulanan | J7: % Bonus | K7: Pinjaman Awal | L7: Sisa Pinjaman
L8: =IF($A8="","",K8-SUMIFS('Penggajian & Slip Gaji'!$U$3:$U$82,'Penggajian & Slip Gaji'!$B$3:$B$82,A8))
L9: =IF($A9="","",K9-SUMIFS('Penggajian & Slip Gaji'!$U$3:$U$82,'Penggajian & Slip Gaji'!$B$3:$B$82,A9))
L10: =IF($A10="","",K10-SUMIFS('Penggajian & Slip Gaji'!$U$3:$U$82,'Penggajian & Slip Gaji'!$B$3:$B$82,A10))
L11: =IF($A11="","",K11-SUMIFS('Penggajian & Slip Gaji'!$U$3:$U$82,'Penggajian & Slip Gaji'!$B$3:$B$82,A11))
L12: =IF($A12="","",K12-SUMIFS('Penggajian & Slip Gaji'!$U$3:$U$82,'Penggajian & Slip Gaji'!$B$3:$B$82,A12))
L13: =IF($A13="","",K13-SUMIFS('Penggajian & Slip Gaji'!$U$3:$U$82,'Penggajian & Slip Gaji'!$B$3:$B$82,A13))
L14: =IF($A14="","",K14-SUMIFS('Penggajian & Slip Gaji'!$U$3:$U$82,'Penggajian & Slip Gaji'!$B$3:$B$82,A14))
L15: =IF($A15="","",K15-SUMIFS('Penggajian & Slip Gaji'!$U$3:$U$82,'Penggajian & Slip Gaji'!$B$3:$B$82,A15))
L16: =IF($A16="","",K16-SUMIFS('Penggajian & Slip Gaji'!$U$3:$U$82,'Penggajian & Slip Gaji'!$B$3:$B$82,A16))
L17: =IF($A17="","",K17-SUMIFS('Penggajian & Slip Gaji'!$U$3:$U$82,'Penggajian & Slip Gaji'!$B$3:$B$82,A17))
L18: =IF($A18="","",K18-SUMIFS('Penggajian & Slip Gaji'!$U$3:$U$82,'Penggajian & Slip Gaji'!$B$3:$B$82,A18))
L19: =IF($A19="","",K19-SUMIFS('Penggajian & Slip Gaji'!$U$3:$U$82,'Penggajian & Slip Gaji'!$B$3:$B$82,A19))
... L37: =IF($A37="","",K37-SUMIFS('Penggajian & Slip Gaji'!$U$3:$U$82,'Penggajian & Slip Gaji'!$B$3:$B$82,A37))

Sheet Absensi Harian
A1: Absensi Harian
A2: Satu baris = satu karyawan pada satu tanggal. Dipakai otomatis oleh sheet Penggajian & Slip Gaji untuk menghitung hari hadir & jam lembur per periode.
A3: Tanggal | B3: Nama Karyawan | C3: Hadir | D3: Jam Lembur

Sheet Penggajian & Slip Gaji
A1: Penggajian & Slip Gaji
A2: No | B2: Nama Karyawan | C2: Jabatan | D2: Tipe Gaji | E2: Periode Mulai | F2: Periode Selesai | G2: Hari Hadir | H2: Upah Harian | I2: Total Upah Harian | J2: Jam Lembur | K2: Tarif Lembur | L2: Total Lembur | M2: Gaji Bulanan | N2: Target | O2: Realisasi | P2: % Bonus | Q2: Bonus Target | R2: Upah Kotor | S2: Uang Makan | T2: Bon | U2: Potongan Pinjaman | V2: Sisa Sebelum | W2: Sisa Sesudah | X2: Gaji Bersih
A3: =IF(B3="","",ROW()-2) | C3: =IF(B3="","",IFERROR(INDEX(Karyawan!$B$8:$B$37,MATCH(B3,Karyawan!$A$8:$A$37,0)),"")) | D3: =IF(B3="","",IFERROR(INDEX(Karyawan!$C$8:$C$37,MATCH(B3,Karyawan!$A$8:$A$37,0)),"")) | G3: =IF(B3="","",COUNTIFS('Absensi Harian'!$B$4:$B$153,B3,'Absensi Harian'!$A$4:$A$153,">="&E3,'Absensi Harian'!$A$4:$A$153,"<="&F3,'Absensi Harian'!$C$4:$C$153,"Ya")) | H3: =IF(B3="","",IFERROR(INDEX(Karyawan!$E$8:$E$37,MATCH(B3,Karyawan!$A$8:$A$37,0)),0)) | I3: =IF(B3="","",G3*H3) | J3: =IF(B3="","",SUMIFS('Absensi Harian'!$D$4:$D$153,'Absensi Harian'!$B$4:$B$153,B3,'Absensi Harian'!$A$4:$A$153,">="&E3,'Absensi Harian'!$A$4:$A$153,"<="&F3,'Absensi Harian'!$C$4:$C$153,"Ya")) | K3: =IF(B3="","",IFERROR(INDEX(Karyawan!$F$8:$F$37,MATCH(B3,Karyawan!$A$8:$A$37,0)),0)) | L3: =IF(B3="","",J3*K3) | M3: =IF(B3="","",IFERROR(INDEX(Karyawan!$H$8:$H$37,MATCH(B3,Karyawan!$A$8:$A$37,0)),0)) | P3: =IF(B3="","",IFERROR(INDEX(Karyawan!$J$8:$J$37,MATCH(B3,Karyawan!$A$8:$A$37,0)),0)) | Q3: =IF(B3="","",MAX(0,O3-N3)*P3) | R3: =IF(B3="","",IF(D3="Bulanan",M3+Q3,I3+L3)) | V3: =IF(B3="","",IFERROR(INDEX(Karyawan!$K$8:$K$37,MATCH(B3,Karyawan!$A$8:$A$37,0)),0)) | W3: =IF(B3="","",V3-U3) | X3: =IF(B3="","",R3-S3-T3-U3)
A4: =IF(B4="","",ROW()-2) | C4: =IF(B4="","",IFERROR(INDEX(Karyawan!$B$8:$B$37,MATCH(B4,Karyawan!$A$8:$A$37,0)),"")) | D4: =IF(B4="","",IFERROR(INDEX(Karyawan!$C$8:$C$37,MATCH(B4,Karyawan!$A$8:$A$37,0)),"")) | G4: =IF(B4="","",COUNTIFS('Absensi Harian'!$B$4:$B$153,B4,'Absensi Harian'!$A$4:$A$153,">="&E4,'Absensi Harian'!$A$4:$A$153,"<="&F4,'Absensi Harian'!$C$4:$C$153,"Ya")) | H4: =IF(B4="","",IFERROR(INDEX(Karyawan!$E$8:$E$37,MATCH(B4,Karyawan!$A$8:$A$37,0)),0)) | I4: =IF(B4="","",G4*H4) | J4: =IF(B4="","",SUMIFS('Absensi Harian'!$D$4:$D$153,'Absensi Harian'!$B$4:$B$153,B4,'Absensi Harian'!$A$4:$A$153,">="&E4,'Absensi Harian'!$A$4:$A$153,"<="&F4,'Absensi Harian'!$C$4:$C$153,"Ya")) | K4: =IF(B4="","",IFERROR(INDEX(Karyawan!$F$8:$F$37,MATCH(B4,Karyawan!$A$8:$A$37,0)),0)) | L4: =IF(B4="","",J4*K4) | M4: =IF(B4="","",IFERROR(INDEX(Karyawan!$H$8:$H$37,MATCH(B4,Karyawan!$A$8:$A$37,0)),0)) | P4: =IF(B4="","",IFERROR(INDEX(Karyawan!$J$8:$J$37,MATCH(B4,Karyawan!$A$8:$A$37,0)),0)) | Q4: =IF(B4="","",MAX(0,O4-N4)*P4) | R4: =IF(B4="","",IF(D4="Bulanan",M4+Q4,I4+L4)) | V4: =IF(B4="","",IFERROR(INDEX(Karyawan!$K$8:$K$37,MATCH(B4,Karyawan!$A$8:$A$37,0)),0)-SUMIFS($U$3:$U3,$B$3:$B3,B4)) | W4: =IF(B4="","",V4-U4) | X4: =IF(B4="","",R4-S4-T4-U4)
A5: =IF(B5="","",ROW()-2) | C5: =IF(B5="","",IFERROR(INDEX(Karyawan!$B$8:$B$37,MATCH(B5,Karyawan!$A$8:$A$37,0)),"")) | D5: =IF(B5="","",IFERROR(INDEX(Karyawan!$C$8:$C$37,MATCH(B5,Karyawan!$A$8:$A$37,0)),"")) | G5: =IF(B5="","",COUNTIFS('Absensi Harian'!$B$4:$B$153,B5,'Absensi Harian'!$A$4:$A$153,">="&E5,'Absensi Harian'!$A$4:$A$153,"<="&F5,'Absensi Harian'!$C$4:$C$153,"Ya")) | H5: =IF(B5="","",IFERROR(INDEX(Karyawan!$E$8:$E$37,MATCH(B5,Karyawan!$A$8:$A$37,0)),0)) | I5: =IF(B5="","",G5*H5) | J5: =IF(B5="","",SUMIFS('Absensi Harian'!$D$4:$D$153,'Absensi Harian'!$B$4:$B$153,B5,'Absensi Harian'!$A$4:$A$153,">="&E5,'Absensi Harian'!$A$4:$A$153,"<="&F5,'Absensi Harian'!$C$4:$C$153,"Ya")) | K5: =IF(B5="","",IFERROR(INDEX(Karyawan!$F$8:$F$37,MATCH(B5,Karyawan!$A$8:$A$37,0)),0)) | L5: =IF(B5="","",J5*K5) | M5: =IF(B5="","",IFERROR(INDEX(Karyawan!$H$8:$H$37,MATCH(B5,Karyawan!$A$8:$A$37,0)),0)) | P5: =IF(B5="","",IFERROR(INDEX(Karyawan!$J$8:$J$37,MATCH(B5,Karyawan!$A$8:$A$37,0)),0)) | Q5: =IF(B5="","",MAX(0,O5-N5)*P5) | R5: =IF(B5="","",IF(D5="Bulanan",M5+Q5,I5+L5)) | V5: =IF(B5="","",IFERROR(INDEX(Karyawan!$K$8:$K$37,MATCH(B5,Karyawan!$A$8:$A$37,0)),0)-SUMIFS($U$3:$U4,$B$3:$B4,B5)) | W5: =IF(B5="","",V5-U5) | X5: =IF(B5="","",R5-S5-T5-U5)
A6: =IF(B6="","",ROW()-2) | C6: =IF(B6="","",IFERROR(INDEX(Karyawan!$B$8:$B$37,MATCH(B6,Karyawan!$A$8:$A$37,0)),"")) | D6: =IF(B6="","",IFERROR(INDEX(Karyawan!$C$8:$C$37,MATCH(B6,Karyawan!$A$8:$A$37,0)),"")) | G6: =IF(B6="","",COUNTIFS('Absensi Harian'!$B$4:$B$153,B6,'Absensi Harian'!$A$4:$A$153,">="&E6,'Absensi Harian'!$A$4:$A$153,"<="&F6,'Absensi Harian'!$C$4:$C$153,"Ya")) | H6: =IF(B6="","",IFERROR(INDEX(Karyawan!$E$8:$E$37,MATCH(B6,Karyawan!$A$8:$A$37,0)),0)) | I6: =IF(B6="","",G6*H6) | J6: =IF(B6="","",SUMIFS('Absensi Harian'!$D$4:$D$153,'Absensi Harian'!$B$4:$B$153,B6,'Absensi Harian'!$A$4:$A$153,">="&E6,'Absensi Harian'!$A$4:$A$153,"<="&F6,'Absensi Harian'!$C$4:$C$153,"Ya")) | K6: =IF(B6="","",IFERROR(INDEX(Karyawan!$F$8:$F$37,MATCH(B6,Karyawan!$A$8:$A$37,0)),0)) | L6: =IF(B6="","",J6*K6) | M6: =IF(B6="","",IFERROR(INDEX(Karyawan!$H$8:$H$37,MATCH(B6,Karyawan!$A$8:$A$37,0)),0)) | P6: =IF(B6="","",IFERROR(INDEX(Karyawan!$J$8:$J$37,MATCH(B6,Karyawan!$A$8:$A$37,0)),0)) | Q6: =IF(B6="","",MAX(0,O6-N6)*P6) | R6: =IF(B6="","",IF(D6="Bulanan",M6+Q6,I6+L6)) | V6: =IF(B6="","",IFERROR(INDEX(Karyawan!$K$8:$K$37,MATCH(B6,Karyawan!$A$8:$A$37,0)),0)-SUMIFS($U$3:$U5,$B$3:$B5,B6)) | W6: =IF(B6="","",V6-U6) | X6: =IF(B6="","",R6-S6-T6-U6)
A7: =IF(B7="","",ROW()-2) | C7: =IF(B7="","",IFERROR(INDEX(Karyawan!$B$8:$B$37,MATCH(B7,Karyawan!$A$8:$A$37,0)),"")) | D7: =IF(B7="","",IFERROR(INDEX(Karyawan!$C$8:$C$37,MATCH(B7,Karyawan!$A$8:$A$37,0)),"")) | G7: =IF(B7="","",COUNTIFS('Absensi Harian'!$B$4:$B$153,B7,'Absensi Harian'!$A$4:$A$153,">="&E7,'Absensi Harian'!$A$4:$A$153,"<="&F7,'Absensi Harian'!$C$4:$C$153,"Ya")) | H7: =IF(B7="","",IFERROR(INDEX(Karyawan!$E$8:$E$37,MATCH(B7,Karyawan!$A$8:$A$37,0)),0)) | I7: =IF(B7="","",G7*H7) | J7: =IF(B7="","",SUMIFS('Absensi Harian'!$D$4:$D$153,'Absensi Harian'!$B$4:$B$153,B7,'Absensi Harian'!$A$4:$A$153,">="&E7,'Absensi Harian'!$A$4:$A$153,"<="&F7,'Absensi Harian'!$C$4:$C$153,"Ya")) | K7: =IF(B7="","",IFERROR(INDEX(Karyawan!$F$8:$F$37,MATCH(B7,Karyawan!$A$8:$A$37,0)),0)) | L7: =IF(B7="","",J7*K7) | M7: =IF(B7="","",IFERROR(INDEX(Karyawan!$H$8:$H$37,MATCH(B7,Karyawan!$A$8:$A$37,0)),0)) | P7: =IF(B7="","",IFERROR(INDEX(Karyawan!$J$8:$J$37,MATCH(B7,Karyawan!$A$8:$A$37,0)),0)) | Q7: =IF(B7="","",MAX(0,O7-N7)*P7) | R7: =IF(B7="","",IF(D7="Bulanan",M7+Q7,I7+L7)) | V7: =IF(B7="","",IFERROR(INDEX(Karyawan!$K$8:$K$37,MATCH(B7,Karyawan!$A$8:$A$37,0)),0)-SUMIFS($U$3:$U6,$B$3:$B6,B7)) | W7: =IF(B7="","",V7-U7) | X7: =IF(B7="","",R7-S7-T7-U7)
A8: =IF(B8="","",ROW()-2) | C8: =IF(B8="","",IFERROR(INDEX(Karyawan!$B$8:$B$37,MATCH(B8,Karyawan!$A$8:$A$37,0)),"")) | D8: =IF(B8="","",IFERROR(INDEX(Karyawan!$C$8:$C$37,MATCH(B8,Karyawan!$A$8:$A$37,0)),"")) | G8: =IF(B8="","",COUNTIFS('Absensi Harian'!$B$4:$B$153,B8,'Absensi Harian'!$A$4:$A$153,">="&E8,'Absensi Harian'!$A$4:$A$153,"<="&F8,'Absensi Harian'!$C$4:$C$153,"Ya")) | H8: =IF(B8="","",IFERROR(INDEX(Karyawan!$E$8:$E$37,MATCH(B8,Karyawan!$A$8:$A$37,0)),0)) | I8: =IF(B8="","",G8*H8) | J8: =IF(B8="","",SUMIFS('Absensi Harian'!$D$4:$D$153,'Absensi Harian'!$B$4:$B$153,B8,'Absensi Harian'!$A$4:$A$153,">="&E8,'Absensi Harian'!$A$4:$A$153,"<="&F8,'Absensi Harian'!$C$4:$C$153,"Ya")) | K8: =IF(B8="","",IFERROR(INDEX(Karyawan!$F$8:$F$37,MATCH(B8,Karyawan!$A$8:$A$37,0)),0)) | L8: =IF(B8="","",J8*K8) | M8: =IF(B8="","",IFERROR(INDEX(Karyawan!$H$8:$H$37,MATCH(B8,Karyawan!$A$8:$A$37,0)),0)) | P8: =IF(B8="","",IFERROR(INDEX(Karyawan!$J$8:$J$37,MATCH(B8,Karyawan!$A$8:$A$37,0)),0)) | Q8: =IF(B8="","",MAX(0,O8-N8)*P8) | R8: =IF(B8="","",IF(D8="Bulanan",M8+Q8,I8+L8)) | V8: =IF(B8="","",IFERROR(INDEX(Karyawan!$K$8:$K$37,MATCH(B8,Karyawan!$A$8:$A$37,0)),0)-SUMIFS($U$3:$U7,$B$3:$B7,B8)) | W8: =IF(B8="","",V8-U8) | X8: =IF(B8="","",R8-S8-T8-U8)
A9: =IF(B9="","",ROW()-2) | C9: =IF(B9="","",IFERROR(INDEX(Karyawan!$B$8:$B$37,MATCH(B9,Karyawan!$A$8:$A$37,0)),"")) | D9: =IF(B9="","",IFERROR(INDEX(Karyawan!$C$8:$C$37,MATCH(B9,Karyawan!$A$8:$A$37,0)),"")) | G9: =IF(B9="","",COUNTIFS('Absensi Harian'!$B$4:$B$153,B9,'Absensi Harian'!$A$4:$A$153,">="&E9,'Absensi Harian'!$A$4:$A$153,"<="&F9,'Absensi Harian'!$C$4:$C$153,"Ya")) | H9: =IF(B9="","",IFERROR(INDEX(Karyawan!$E$8:$E$37,MATCH(B9,Karyawan!$A$8:$A$37,0)),0)) | I9: =IF(B9="","",G9*H9) | J9: =IF(B9="","",SUMIFS('Absensi Harian'!$D$4:$D$153,'Absensi Harian'!$B$4:$B$153,B9,'Absensi Harian'!$A$4:$A$153,">="&E9,'Absensi Harian'!$A$4:$A$153,"<="&F9,'Absensi Harian'!$C$4:$C$153,"Ya")) | K9: =IF(B9="","",IFERROR(INDEX(Karyawan!$F$8:$F$37,MATCH(B9,Karyawan!$A$8:$A$37,0)),0)) | L9: =IF(B9="","",J9*K9) | M9: =IF(B9="","",IFERROR(INDEX(Karyawan!$H$8:$H$37,MATCH(B9,Karyawan!$A$8:$A$37,0)),0)) | P9: =IF(B9="","",IFERROR(INDEX(Karyawan!$J$8:$J$37,MATCH(B9,Karyawan!$A$8:$A$37,0)),0)) | Q9: =IF(B9="","",MAX(0,O9-N9)*P9) | R9: =IF(B9="","",IF(D9="Bulanan",M9+Q9,I9+L9)) | V9: =IF(B9="","",IFERROR(INDEX(Karyawan!$K$8:$K$37,MATCH(B9,Karyawan!$A$8:$A$37,0)),0)-SUMIFS($U$3:$U8,$B$3:$B8,B9)) | W9: =IF(B9="","",V9-U9) | X9: =IF(B9="","",R9-S9-T9-U9)
A10: =IF(B10="","",ROW()-2) | C10: =IF(B10="","",IFERROR(INDEX(Karyawan!$B$8:$B$37,MATCH(B10,Karyawan!$A$8:$A$37,0)),"")) | D10: =IF(B10="","",IFERROR(INDEX(Karyawan!$C$8:$C$37,MATCH(B10,Karyawan!$A$8:$A$37,0)),"")) | G10: =IF(B10="","",COUNTIFS('Absensi Harian'!$B$4:$B$153,B10,'Absensi Harian'!$A$4:$A$153,">="&E10,'Absensi Harian'!$A$4:$A$153,"<="&F10,'Absensi Harian'!$C$4:$C$153,"Ya")) | H10: =IF(B10="","",IFERROR(INDEX(Karyawan!$E$8:$E$37,MATCH(B10,Karyawan!$A$8:$A$37,0)),0)) | I10: =IF(B10="","",G10*H10) | J10: =IF(B10="","",SUMIFS('Absensi Harian'!$D$4:$D$153,'Absensi Harian'!$B$4:$B$153,B10,'Absensi Harian'!$A$4:$A$153,">="&E10,'Absensi Harian'!$A$4:$A$153,"<="&F10,'Absensi Harian'!$C$4:$C$153,"Ya")) | K10: =IF(B10="","",IFERROR(INDEX(Karyawan!$F$8:$F$37,MATCH(B10,Karyawan!$A$8:$A$37,0)),0)) | L10: =IF(B10="","",J10*K10) | M10: =IF(B10="","",IFERROR(INDEX(Karyawan!$H$8:$H$37,MATCH(B10,Karyawan!$A$8:$A$37,0)),0)) | P10: =IF(B10="","",IFERROR(INDEX(Karyawan!$J$8:$J$37,MATCH(B10,Karyawan!$A$8:$A$37,0)),0)) | Q10: =IF(B10="","",MAX(0,O10-N10)*P10) | R10: =IF(B10="","",IF(D10="Bulanan",M10+Q10,I10+L10)) | V10: =IF(B10="","",IFERROR(INDEX(Karyawan!$K$8:$K$37,MATCH(B10,Karyawan!$A$8:$A$37,0)),0)-SUMIFS($U$3:$U9,$B$3:$B9,B10)) | W10: =IF(B10="","",V10-U10) | X10: =IF(B10="","",R10-S10-T10-U10)
A11: =IF(B11="","",ROW()-2) | C11: =IF(B11="","",IFERROR(INDEX(Karyawan!$B$8:$B$37,MATCH(B11,Karyawan!$A$8:$A$37,0)),"")) | D11: =IF(B11="","",IFERROR(INDEX(Karyawan!$C$8:$C$37,MATCH(B11,Karyawan!$A$8:$A$37,0)),"")) | G11: =IF(B11="","",COUNTIFS('Absensi Harian'!$B$4:$B$153,B11,'Absensi Harian'!$A$4:$A$153,">="&E11,'Absensi Harian'!$A$4:$A$153,"<="&F11,'Absensi Harian'!$C$4:$C$153,"Ya")) | H11: =IF(B11="","",IFERROR(INDEX(Karyawan!$E$8:$E$37,MATCH(B11,Karyawan!$A$8:$A$37,0)),0)) | I11: =IF(B11="","",G11*H11) | J11: =IF(B11="","",SUMIFS('Absensi Harian'!$D$4:$D$153,'Absensi Harian'!$B$4:$B$153,B11,'Absensi Harian'!$A$4:$A$153,">="&E11,'Absensi Harian'!$A$4:$A$153,"<="&F11,'Absensi Harian'!$C$4:$C$153,"Ya")) | K11: =IF(B11="","",IFERROR(INDEX(Karyawan!$F$8:$F$37,MATCH(B11,Karyawan!$A$8:$A$37,0)),0)) | L11: =IF(B11="","",J11*K11) | M11: =IF(B11="","",IFERROR(INDEX(Karyawan!$H$8:$H$37,MATCH(B11,Karyawan!$A$8:$A$37,0)),0)) | P11: =IF(B11="","",IFERROR(INDEX(Karyawan!$J$8:$J$37,MATCH(B11,Karyawan!$A$8:$A$37,0)),0)) | Q11: =IF(B11="","",MAX(0,O11-N11)*P11) | R11: =IF(B11="","",IF(D11="Bulanan",M11+Q11,I11+L11)) | V11: =IF(B11="","",IFERROR(INDEX(Karyawan!$K$8:$K$37,MATCH(B11,Karyawan!$A$8:$A$37,0)),0)-SUMIFS($U$3:$U10,$B$3:$B10,B11)) | W11: =IF(B11="","",V11-U11) | X11: =IF(B11="","",R11-S11-T11-U11)
A12: =IF(B12="","",ROW()-2) | C12: =IF(B12="","",IFERROR(INDEX(Karyawan!$B$8:$B$37,MATCH(B12,Karyawan!$A$8:$A$37,0)),"")) | D12: =IF(B12="","",IFERROR(INDEX(Karyawan!$C$8:$C$37,MATCH(B12,Karyawan!$A$8:$A$37,0)),"")) | G12: =IF(B12="","",COUNTIFS('Absensi Harian'!$B$4:$B$153,B12,'Absensi Harian'!$A$4:$A$153,">="&E12,'Absensi Harian'!$A$4:$A$153,"<="&F12,'Absensi Harian'!$C$4:$C$153,"Ya")) | H12: =IF(B12="","",IFERROR(INDEX(Karyawan!$E$8:$E$37,MATCH(B12,Karyawan!$A$8:$A$37,0)),0)) | I12: =IF(B12="","",G12*H12) | J12: =IF(B12="","",SUMIFS('Absensi Harian'!$D$4:$D$153,'Absensi Harian'!$B$4:$B$153,B12,'Absensi Harian'!$A$4:$A$153,">="&E12,'Absensi Harian'!$A$4:$A$153,"<="&F12,'Absensi Harian'!$C$4:$C$153,"Ya")) | K12: =IF(B12="","",IFERROR(INDEX(Karyawan!$F$8:$F$37,MATCH(B12,Karyawan!$A$8:$A$37,0)),0)) | L12: =IF(B12="","",J12*K12) | M12: =IF(B12="","",IFERROR(INDEX(Karyawan!$H$8:$H$37,MATCH(B12,Karyawan!$A$8:$A$37,0)),0)) | P12: =IF(B12="","",IFERROR(INDEX(Karyawan!$J$8:$J$37,MATCH(B12,Karyawan!$A$8:$A$37,0)),0)) | Q12: =IF(B12="","",MAX(0,O12-N12)*P12) | R12: =IF(B12="","",IF(D12="Bulanan",M12+Q12,I12+L12)) | V12: =IF(B12="","",IFERROR(INDEX(Karyawan!$K$8:$K$37,MATCH(B12,Karyawan!$A$8:$A$37,0)),0)-SUMIFS($U$3:$U11,$B$3:$B11,B12)) | W12: =IF(B12="","",V12-U12) | X12: =IF(B12="","",R12-S12-T12-U12)
A13: =IF(B13="","",ROW()-2) | C13: =IF(B13="","",IFERROR(INDEX(Karyawan!$B$8:$B$37,MATCH(B13,Karyawan!$A$8:$A$37,0)),"")) | D13: =IF(B13="","",IFERROR(INDEX(Karyawan!$C$8:$C$37,MATCH(B13,Karyawan!$A$8:$A$37,0)),"")) | G13: =IF(B13="","",COUNTIFS('Absensi Harian'!$B$4:$B$153,B13,'Absensi Harian'!$A$4:$A$153,">="&E13,'Absensi Harian'!$A$4:$A$153,"<="&F13,'Absensi Harian'!$C$4:$C$153,"Ya")) | H13: =IF(B13="","",IFERROR(INDEX(Karyawan!$E$8:$E$37,MATCH(B13,Karyawan!$A$8:$A$37,0)),0)) | I13: =IF(B13="","",G13*H13) | J13: =IF(B13="","",SUMIFS('Absensi Harian'!$D$4:$D$153,'Absensi Harian'!$B$4:$B$153,B13,'Absensi Harian'!$A$4:$A$153,">="&E13,'Absensi Harian'!$A$4:$A$153,"<="&F13,'Absensi Harian'!$C$4:$C$153,"Ya")) | K13: =IF(B13="","",IFERROR(INDEX(Karyawan!$F$8:$F$37,MATCH(B13,Karyawan!$A$8:$A$37,0)),0)) | L13: =IF(B13="","",J13*K13) | M13: =IF(B13="","",IFERROR(INDEX(Karyawan!$H$8:$H$37,MATCH(B13,Karyawan!$A$8:$A$37,0)),0)) | P13: =IF(B13="","",IFERROR(INDEX(Karyawan!$J$8:$J$37,MATCH(B13,Karyawan!$A$8:$A$37,0)),0)) | Q13: =IF(B13="","",MAX(0,O13-N13)*P13) | R13: =IF(B13="","",IF(D13="Bulanan",M13+Q13,I13+L13)) | V13: =IF(B13="","",IFERROR(INDEX(Karyawan!$K$8:$K$37,MATCH(B13,Karyawan!$A$8:$A$37,0)),0)-SUMIFS($U$3:$U12,$B$3:$B12,B13)) | W13: =IF(B13="","",V13-U13) | X13: =IF(B13="","",R13-S13-T13-U13)
A14: =IF(B14="","",ROW()-2) | C14: =IF(B14="","",IFERROR(INDEX(Karyawan!$B$8:$B$37,MATCH(B14,Karyawan!$A$8:$A$37,0)),"")) | D14: =IF(B14="","",IFERROR(INDEX(Karyawan!$C$8:$C$37,MATCH(B14,Karyawan!$A$8:$A$37,0)),"")) | G14: =IF(B14="","",COUNTIFS('Absensi Harian'!$B$4:$B$153,B14,'Absensi Harian'!$A$4:$A$153,">="&E14,'Absensi Harian'!$A$4:$A$153,"<="&F14,'Absensi Harian'!$C$4:$C$153,"Ya")) | H14: =IF(B14="","",IFERROR(INDEX(Karyawan!$E$8:$E$37,MATCH(B14,Karyawan!$A$8:$A$37,0)),0)) | I14: =IF(B14="","",G14*H14) | J14: =IF(B14="","",SUMIFS('Absensi Harian'!$D$4:$D$153,'Absensi Harian'!$B$4:$B$153,B14,'Absensi Harian'!$A$4:$A$153,">="&E14,'Absensi Harian'!$A$4:$A$153,"<="&F14,'Absensi Harian'!$C$4:$C$153,"Ya")) | K14: =IF(B14="","",IFERROR(INDEX(Karyawan!$F$8:$F$37,MATCH(B14,Karyawan!$A$8:$A$37,0)),0)) | L14: =IF(B14="","",J14*K14) | M14: =IF(B14="","",IFERROR(INDEX(Karyawan!$H$8:$H$37,MATCH(B14,Karyawan!$A$8:$A$37,0)),0)) | P14: =IF(B14="","",IFERROR(INDEX(Karyawan!$J$8:$J$37,MATCH(B14,Karyawan!$A$8:$A$37,0)),0)) | Q14: =IF(B14="","",MAX(0,O14-N14)*P14) | R14: =IF(B14="","",IF(D14="Bulanan",M14+Q14,I14+L14)) | V14: =IF(B14="","",IFERROR(INDEX(Karyawan!$K$8:$K$37,MATCH(B14,Karyawan!$A$8:$A$37,0)),0)-SUMIFS($U$3:$U13,$B$3:$B13,B14)) | W14: =IF(B14="","",V14-U14) | X14: =IF(B14="","",R14-S14-T14-U14)
A15: =IF(B15="","",ROW()-2) | C15: =IF(B15="","",IFERROR(INDEX(Karyawan!$B$8:$B$37,MATCH(B15,Karyawan!$A$8:$A$37,0)),"")) | D15: =IF(B15="","",IFERROR(INDEX(Karyawan!$C$8:$C$37,MATCH(B15,Karyawan!$A$8:$A$37,0)),"")) | G15: =IF(B15="","",COUNTIFS('Absensi Harian'!$B$4:$B$153,B15,'Absensi Harian'!$A$4:$A$153,">="&E15,'Absensi Harian'!$A$4:$A$153,"<="&F15,'Absensi Harian'!$C$4:$C$153,"Ya")) | H15: =IF(B15="","",IFERROR(INDEX(Karyawan!$E$8:$E$37,MATCH(B15,Karyawan!$A$8:$A$37,0)),0)) | I15: =IF(B15="","",G15*H15) | J15: =IF(B15="","",SUMIFS('Absensi Harian'!$D$4:$D$153,'Absensi Harian'!$B$4:$B$153,B15,'Absensi Harian'!$A$4:$A$153,">="&E15,'Absensi Harian'!$A$4:$A$153,"<="&F15,'Absensi Harian'!$C$4:$C$153,"Ya")) | K15: =IF(B15="","",IFERROR(INDEX(Karyawan!$F$8:$F$37,MATCH(B15,Karyawan!$A$8:$A$37,0)),0)) | L15: =IF(B15="","",J15*K15) | M15: =IF(B15="","",IFERROR(INDEX(Karyawan!$H$8:$H$37,MATCH(B15,Karyawan!$A$8:$A$37,0)),0)) | P15: =IF(B15="","",IFERROR(INDEX(Karyawan!$J$8:$J$37,MATCH(B15,Karyawan!$A$8:$A$37,0)),0)) | Q15: =IF(B15="","",MAX(0,O15-N15)*P15) | R15: =IF(B15="","",IF(D15="Bulanan",M15+Q15,I15+L15)) | V15: =IF(B15="","",IFERROR(INDEX(Karyawan!$K$8:$K$37,MATCH(B15,Karyawan!$A$8:$A$37,0)),0)-SUMIFS($U$3:$U14,$B$3:$B14,B15)) | W15: =IF(B15="","",V15-U15) | X15: =IF(B15="","",R15-S15-T15-U15)
... A82: =IF(B82="","",ROW()-2) | C82: =IF(B82="","",IFERROR(INDEX(Karyawan!$B$8:$B$37,MATCH(B82,Karyawan!$A$8:$A$37,0)),"")) | D82: =IF(B82="","",IFERROR(INDEX(Karyawan!$C$8:$C$37,MATCH(B82,Karyawan!$A$8:$A$37,0)),"")) | G82: =IF(B82="","",COUNTIFS('Absensi Harian'!$B$4:$B$153,B82,'Absensi Harian'!$A$4:$A$153,">="&E82,'Absensi Harian'!$A$4:$A$153,"<="&F82,'Absensi Harian'!$C$4:$C$153,"Ya")) | H82: =IF(B82="","",IFERROR(INDEX(Karyawan!$E$8:$E$37,MATCH(B82,Karyawan!$A$8:$A$37,0)),0)) | I82: =IF(B82="","",G82*H82) | J82: =IF(B82="","",SUMIFS('Absensi Harian'!$D$4:$D$153,'Absensi Harian'!$B$4:$B$153,B82,'Absensi Harian'!$A$4:$A$153,">="&E82,'Absensi Harian'!$A$4:$A$153,"<="&F82,'Absensi Harian'!$C$4:$C$153,"Ya")) | K82: =IF(B82="","",IFERROR(INDEX(Karyawan!$F$8:$F$37,MATCH(B82,Karyawan!$A$8:$A$37,0)),0)) | L82: =IF(B82="","",J82*K82) | M82: =IF(B82="","",IFERROR(INDEX(Karyawan!$H$8:$H$37,MATCH(B82,Karyawan!$A$8:$A$37,0)),0)) | P82: =IF(B82="","",IFERROR(INDEX(Karyawan!$J$8:$J$37,MATCH(B82,Karyawan!$A$8:$A$37,0)),0)) | Q82: =IF(B82="","",MAX(0,O82-N82)*P82) | R82: =IF(B82="","",IF(D82="Bulanan",M82+Q82,I82+L82)) | V82: =IF(B82="","",IFERROR(INDEX(Karyawan!$K$8:$K$37,MATCH(B82,Karyawan!$A$8:$A$37,0)),0)-SUMIFS($U$3:$U81,$B$3:$B81,B82)) | W82: =IF(B82="","",V82-U82) | X82: =IF(B82="","",R82-S82-T82-U82)

Sheet Cetak Slip Gaji
B2: Pilih No Slip:
A5: =CompanyName -> CV Mitra Creative
A6: =CompanyAddress&" - "&CompanyPhone -> Jl. Taman Asri No. 15, Pedurungan Tengah, Semarang - 0895811220203
A8: SLIP GAJI KARYAWAN
A10: Nama | B10: =IF($C$2="","",IFERROR(INDEX('Penggajian & Slip Gaji'!$B$3:$B$82,MATCH($C$2,'Penggajian & Slip Gaji'!$A$3:$A$82,0)),""))
A11: Jabatan | B11: =IF($C$2="","",IFERROR(INDEX('Penggajian & Slip Gaji'!$C$3:$C$82,MATCH($C$2,'Penggajian & Slip Gaji'!$A$3:$A$82,0)),""))
A12: Periode Mulai | B12: =IF($C$2="","",IFERROR(INDEX('Penggajian & Slip Gaji'!$E$3:$E$82,MATCH($C$2,'Penggajian & Slip Gaji'!$A$3:$A$82,0)),""))
A13: Periode Selesai | B13: =IF($C$2="","",IFERROR(INDEX('Penggajian & Slip Gaji'!$F$3:$F$82,MATCH($C$2,'Penggajian & Slip Gaji'!$A$3:$A$82,0)),""))
A15: Upah Kotor | B15: =IF($C$2="","",IFERROR(INDEX('Penggajian & Slip Gaji'!$R$3:$R$82,MATCH($C$2,'Penggajian & Slip Gaji'!$A$3:$A$82,0)),""))
A16: Uang Makan | B16: =IF($C$2="","",IFERROR(INDEX('Penggajian & Slip Gaji'!$S$3:$S$82,MATCH($C$2,'Penggajian & Slip Gaji'!$A$3:$A$82,0)),""))
A17: Bon | B17: =IF($C$2="","",IFERROR(INDEX('Penggajian & Slip Gaji'!$T$3:$T$82,MATCH($C$2,'Penggajian & Slip Gaji'!$A$3:$A$82,0)),""))
A18: Potongan Pinjaman | B18: =IF($C$2="","",IFERROR(INDEX('Penggajian & Slip Gaji'!$U$3:$U$82,MATCH($C$2,'Penggajian & Slip Gaji'!$A$3:$A$82,0)),""))
A19: Sisa Pinjaman Sebelum | B19: =IF($C$2="","",IFERROR(INDEX('Penggajian & Slip Gaji'!$V$3:$V$82,MATCH($C$2,'Penggajian & Slip Gaji'!$A$3:$A$82,0)),""))
A20: Sisa Pinjaman Sesudah | B20: =IF($C$2="","",IFERROR(INDEX('Penggajian & Slip Gaji'!$W$3:$W$82,MATCH($C$2,'Penggajian & Slip Gaji'!$A$3:$A$82,0)),""))
A21: GAJI BERSIH (Take Home) | B21: =IF($C$2="","",IFERROR(INDEX('Penggajian & Slip Gaji'!$X$3:$X$82,MATCH($C$2,'Penggajian & Slip Gaji'!$A$3:$A$82,0)),""))
A23: =OwnerName -> Aditya Khresna
A24: =OwnerJabatan -> Owner / Direktur

Sheet Stok Material & Alat
A1: Stok Material & Alat
A2: Stok saat ini dihitung otomatis dari sheet 'Stok - Riwayat' (barang masuk/keluar) — tidak pernah ditimpa manual, jadi selalu bisa diaudit.
B3: Total Jenis Barang | C3: Total Nilai Stok | D3: Hampir Habis | E3: Stok Habis
B4: =COUNTA(A8:A47) -> 0 | C4: =SUM(H8:H47) -> 0 | D4: =COUNTIF(I8:I47,"Hampir Habis") -> 0 | E4: =COUNTIF(I8:I47,"Habis") -> 0
A7: Nama Barang | B7: Kategori | C7: Satuan | D7: Stok Awal | E7: Stok Minimum | F7: Harga Satuan | G7: Stok Saat Ini | H7: Nilai Stok | I7: Status
G8: =IF($A8="","",D8+SUMIFS('Stok - Riwayat'!$D$8:$D$157,'Stok - Riwayat'!$A$8:$A$157,A8,'Stok - Riwayat'!$C$8:$C$157,"Masuk")-SUMIFS('Stok - Riwayat'!$D$8:$D$157,'Stok - Riwayat'!$A$8:$A$157,A8,'Stok - Riwayat'!$C$8:$C$157,"Keluar")) | H8: =IF($A8="","",G8*F8) | I8: =IF($A8="","",IF(G8<=0,"Habis",IF(G8<=E8,"Hampir Habis","Aman")))
G9: =IF($A9="","",D9+SUMIFS('Stok - Riwayat'!$D$8:$D$157,'Stok - Riwayat'!$A$8:$A$157,A9,'Stok - Riwayat'!$C$8:$C$157,"Masuk")-SUMIFS('Stok - Riwayat'!$D$8:$D$157,'Stok - Riwayat'!$A$8:$A$157,A9,'Stok - Riwayat'!$C$8:$C$157,"Keluar")) | H9: =IF($A9="","",G9*F9) | I9: =IF($A9="","",IF(G9<=0,"Habis",IF(G9<=E9,"Hampir Habis","Aman")))
G10: =IF($A10="","",D10+SUMIFS('Stok - Riwayat'!$D$8:$D$157,'Stok - Riwayat'!$A$8:$A$157,A10,'Stok - Riwayat'!$C$8:$C$157,"Masuk")-SUMIFS('Stok - Riwayat'!$D$8:$D$157,'Stok - Riwayat'!$A$8:$A$157,A10,'Stok - Riwayat'!$C$8:$C$157,"Keluar")) | H10: =IF($A10="","",G10*F10) | I10: =IF($A10="","",IF(G10<=0,"Habis",IF(G10<=E10,"Hampir Habis","Aman")))
G11: =IF($A11="","",D11+SUMIFS('Stok - Riwayat'!$D$8:$D$157,'Stok - Riwayat'!$A$8:$A$157,A11,'Stok - Riwayat'!$C$8:$C$157,"Masuk")-SUMIFS('Stok - Riwayat'!$D$8:$D$157,'Stok - Riwayat'!$A$8:$A$157,A11,'Stok - Riwayat'!$C$8:$C$157,"Keluar")) | H11: =IF($A11="","",G11*F11) | I11: =IF($A11="","",IF(G11<=0,"Habis",IF(G11<=E11,"Hampir Habis","Aman")))
G12: =IF($A12="","",D12+SUMIFS('Stok - Riwayat'!$D$8:$D$157,'Stok - Riwayat'!$A$8:$A$157,A12,'Stok - Riwayat'!$C$8:$C$157,"Masuk")-SUMIFS('Stok - Riwayat'!$D$8:$D$157,'Stok - Riwayat'!$A$8:$A$157,A12,'Stok - Riwayat'!$C$8:$C$157,"Keluar")) | H12: =IF($A12="","",G12*F12) | I12: =IF($A12="","",IF(G12<=0,"Habis",IF(G12<=E12,"Hampir Habis","Aman")))
G13: =IF($A13="","",D13+SUMIFS('Stok - Riwayat'!$D$8:$D$157,'Stok - Riwayat'!$A$8:$A$157,A13,'Stok - Riwayat'!$C$8:$C$157,"Masuk")-SUMIFS('Stok - Riwayat'!$D$8:$D$157,'Stok - Riwayat'!$A$8:$A$157,A13,'Stok - Riwayat'!$C$8:$C$157,"Keluar")) | H13: =IF($A13="","",G13*F13) | I13: =IF($A13="","",IF(G13<=0,"Habis",IF(G13<=E13,"Hampir Habis","Aman")))
G14: =IF($A14="","",D14+SUMIFS('Stok - Riwayat'!$D$8:$D$157,'Stok - Riwayat'!$A$8:$A$157,A14,'Stok - Riwayat'!$C$8:$C$157,"Masuk")-SUMIFS('Stok - Riwayat'!$D$8:$D$157,'Stok - Riwayat'!$A$8:$A$157,A14,'Stok - Riwayat'!$C$8:$C$157,"Keluar")) | H14: =IF($A14="","",G14*F14) | I14: =IF($A14="","",IF(G14<=0,"Habis",IF(G14<=E14,"Hampir Habis","Aman")))
G15: =IF($A15="","",D15+SUMIFS('Stok - Riwayat'!$D$8:$D$157,'Stok - Riwayat'!$A$8:$A$157,A15,'Stok - Riwayat'!$C$8:$C$157,"Masuk")-SUMIFS('Stok - Riwayat'!$D$8:$D$157,'Stok - Riwayat'!$A$8:$A$157,A15,'Stok - Riwayat'!$C$8:$C$157,"Keluar")) | H15: =IF($A15="","",G15*F15) | I15: =IF($A15="","",IF(G15<=0,"Habis",IF(G15<=E15,"Hampir Habis","Aman")))
G16: =IF($A16="","",D16+SUMIFS('Stok - Riwayat'!$D$8:$D$157,'Stok - Riwayat'!$A$8:$A$157,A16,'Stok - Riwayat'!$C$8:$C$157,"Masuk")-SUMIFS('Stok - Riwayat'!$D$8:$D$157,'Stok - Riwayat'!$A$8:$A$157,A16,'Stok - Riwayat'!$C$8:$C$157,"Keluar")) | H16: =IF($A16="","",G16*F16) | I16: =IF($A16="","",IF(G16<=0,"Habis",IF(G16<=E16,"Hampir Habis","Aman")))
G17: =IF($A17="","",D17+SUMIFS('Stok - Riwayat'!$D$8:$D$157,'Stok - Riwayat'!$A$8:$A$157,A17,'Stok - Riwayat'!$C$8:$C$157,"Masuk")-SUMIFS('Stok - Riwayat'!$D$8:$D$157,'Stok - Riwayat'!$A$8:$A$157,A17,'Stok - Riwayat'!$C$8:$C$157,"Keluar")) | H17: =IF($A17="","",G17*F17) | I17: =IF($A17="","",IF(G17<=0,"Habis",IF(G17<=E17,"Hampir Habis","Aman")))
G18: =IF($A18="","",D18+SUMIFS('Stok - Riwayat'!$D$8:$D$157,'Stok - Riwayat'!$A$8:$A$157,A18,'Stok - Riwayat'!$C$8:$C$157,"Masuk")-SUMIFS('Stok - Riwayat'!$D$8:$D$157,'Stok - Riwayat'!$A$8:$A$157,A18,'Stok - Riwayat'!$C$8:$C$157,"Keluar")) | H18: =IF($A18="","",G18*F18) | I18: =IF($A18="","",IF(G18<=0,"Habis",IF(G18<=E18,"Hampir Habis","Aman")))
G19: =IF($A19="","",D19+SUMIFS('Stok - Riwayat'!$D$8:$D$157,'Stok - Riwayat'!$A$8:$A$157,A19,'Stok - Riwayat'!$C$8:$C$157,"Masuk")-SUMIFS('Stok - Riwayat'!$D$8:$D$157,'Stok - Riwayat'!$A$8:$A$157,A19,'Stok - Riwayat'!$C$8:$C$157,"Keluar")) | H19: =IF($A19="","",G19*F19) | I19: =IF($A19="","",IF(G19<=0,"Habis",IF(G19<=E19,"Hampir Habis","Aman")))
... G47: =IF($A47="","",D47+SUMIFS('Stok - Riwayat'!$D$8:$D$157,'Stok - Riwayat'!$A$8:$A$157,A47,'Stok - Riwayat'!$C$8:$C$157,"Masuk")-SUMIFS('Stok - Riwayat'!$D$8:$D$157,'Stok - Riwayat'!$A$8:$A$157,A47,'Stok - Riwayat'!$C$8:$C$157,"Keluar")) | H47: =IF($A47="","",G47*F47) | I47: =IF($A47="","",IF(G47<=0,"Habis",IF(G47<=E47,"Hampir Habis","Aman")))

Sheet Stok - Riwayat
A1: Stok - Riwayat Transaksi
A2: Catat setiap barang masuk (pembelian/restock) dan keluar (pemakaian proyek). Sheet 'Stok Material & Alat' otomatis mengikuti riwayat ini.
A3: Nama Barang | B3: Tanggal | C3: Tipe | D3: Qty | E3: Keterangan

Sheet AHSP
A1: AHSP — Analisa Harga Satuan Pekerjaan
A2: Database harga satuan per kategori usaha. Kode dipakai untuk ambil harga otomatis di RAB & Penawaran. Mode 'Detail': isi rincian komponen di sheet 'AHSP - Komponen' (harga terhitung otomatis + overhead%).
A3: Kategori | B3: Kode | C3: Uraian Pekerjaan | D3: Satuan | E3: Mode | F3: Harga Manual | G3: Overhead % | H3: Subtotal Komponen | I3: Harga Satuan Final
A4: Sipil/Konstruksi | B4: SIP-01 | C4: Pasangan Bata Merah 1:4 | D4: m2 | E4: Detail | F4: 0 | G4: 0.1 | H4: =IF($B4="","",SUMIFS('AHSP - Komponen'!$G$8:$G$87,'AHSP - Komponen'!$A$8:$A$87,B4)) -> 172706 | I4: =IF($B4="","",IF(E4="Manual",F4,H4*(1+G4))) -> 189976.6
A5: Sipil/Konstruksi | B5: SIP-02 | C5: Plesteran 1:4 Tebal 15mm | D5: m2 | E5: Detail | F5: 0 | G5: 0.1 | H5: =IF($B5="","",SUMIFS('AHSP - Komponen'!$G$8:$G$87,'AHSP - Komponen'!$A$8:$A$87,B5)) -> 63556 | I5: =IF($B5="","",IF(E5="Manual",F5,H5*(1+G5))) -> 69911.6
A6: Sipil/Konstruksi | B6: SIP-03 | C6: Pengecatan Dinding (2x lapis) | D6: m2 | E6: Manual | F6: 35000 | G6: 0 | H6: =IF($B6="","",SUMIFS('AHSP - Komponen'!$G$8:$G$87,'AHSP - Komponen'!$A$8:$A$87,B6)) -> 0 | I6: =IF($B6="","",IF(E6="Manual",F6,H6*(1+G6))) -> 35000
A7: Advertising | B7: ADV-01 | C7: Pembuatan & Pemasangan Neon Box Acrylic | D7: m2 | E7: Manual | F7: 850000 | G7: 0 | H7: =IF($B7="","",SUMIFS('AHSP - Komponen'!$G$8:$G$87,'AHSP - Komponen'!$A$8:$A$87,B7)) -> 0 | I7: =IF($B7="","",IF(E7="Manual",F7,H7*(1+G7))) -> 850000
A8: Advertising | B8: ADV-02 | C8: Cetak Baliho Flexy Frontlite + Rangka Kayu | D8: m2 | E8: Manual | F8: 65000 | G8: 0 | H8: =IF($B8="","",SUMIFS('AHSP - Komponen'!$G$8:$G$87,'AHSP - Komponen'!$A$8:$A$87,B8)) -> 0 | I8: =IF($B8="","",IF(E8="Manual",F8,H8*(1+G8))) -> 65000
A9: Advertising | B9: ADV-03 | C9: Pemasangan Huruf Timbul Galvanis + Cat Duco | D9: m2 | E9: Manual | F9: 950000 | G9: 0 | H9: =IF($B9="","",SUMIFS('AHSP - Komponen'!$G$8:$G$87,'AHSP - Komponen'!$A$8:$A$87,B9)) -> 0 | I9: =IF($B9="","",IF(E9="Manual",F9,H9*(1+G9))) -> 950000
A10: Renovasi Interior | B10: INT-01 | C10: Pemasangan Plafon Gypsum + Rangka Hollow | D10: m2 | E10: Detail | F10: 0 | G10: 0.1 | H10: =IF($B10="","",SUMIFS('AHSP - Komponen'!$G$8:$G$87,'AHSP - Komponen'!$A$8:$A$87,B10)) -> 102850 | I10: =IF($B10="","",IF(E10="Manual",F10,H10*(1+G10))) -> 113135
A11: Renovasi Interior | B11: INT-02 | C11: Pemasangan Keramik Lantai 60x60 | D11: m2 | E11: Manual | F11: 140000 | G11: 0 | H11: =IF($B11="","",SUMIFS('AHSP - Komponen'!$G$8:$G$87,'AHSP - Komponen'!$A$8:$A$87,B11)) -> 0 | I11: =IF($B11="","",IF(E11="Manual",F11,H11*(1+G11))) -> 140000
A12: Renovasi Eksterior | B12: EKS-01 | C12: Pengecatan Fasad Eksterior Weathershield | D12: m2 | E12: Manual | F12: 45000 | G12: 0 | H12: =IF($B12="","",SUMIFS('AHSP - Komponen'!$G$8:$G$87,'AHSP - Komponen'!$A$8:$A$87,B12)) -> 0 | I12: =IF($B12="","",IF(E12="Manual",F12,H12*(1+G12))) -> 45000
A13: Renovasi Eksterior | B13: EKS-02 | C13: Pemasangan Kanopi Baja Ringan + Atap Spandek | D13: m2 | E13: Manual | F13: 350000 | G13: 0 | H13: =IF($B13="","",SUMIFS('AHSP - Komponen'!$G$8:$G$87,'AHSP - Komponen'!$A$8:$A$87,B13)) -> 0 | I13: =IF($B13="","",IF(E13="Manual",F13,H13*(1+G13))) -> 350000
A14: Event Organizer | B14: EO-01 | C14: Sewa & Pemasangan Tenda Sarnavil + Kursi | D14: paket | E14: Manual | F14: 5000000 | G14: 0 | H14: =IF($B14="","",SUMIFS('AHSP - Komponen'!$G$8:$G$87,'AHSP - Komponen'!$A$8:$A$87,B14)) -> 0 | I14: =IF($B14="","",IF(E14="Manual",F14,H14*(1+G14))) -> 5000000
A15: Event Organizer | B15: EO-02 | C15: Dekorasi Panggung + Backdrop Event | D15: paket | E15: Manual | F15: 8000000 | G15: 0 | H15: =IF($B15="","",SUMIFS('AHSP - Komponen'!$G$8:$G$87,'AHSP - Komponen'!$A$8:$A$87,B15)) -> 0 | I15: =IF($B15="","",IF(E15="Manual",F15,H15*(1+G15))) -> 8000000
... A22: Gudang Gadai Sakti | B22: GS-04 | C22: Plafond Wiremesh + Hollow Blacksteel | D22: m2 | E22: Manual | F22: 0 | G22: 0 | H22: =IF($B22="","",SUMIFS('AHSP - Komponen'!$G$8:$G$87,'AHSP - Komponen'!$A$8:$A$87,B22)) -> 0 | I22: =IF($B22="","",IF(E22="Manual",F22,H22*(1+G22))) -> 0
H23: =IF($B23="","",SUMIFS('AHSP - Komponen'!$G$8:$G$87,'AHSP - Komponen'!$A$8:$A$87,B23)) | I23: =IF($B23="","",IF(E23="Manual",F23,H23*(1+G23)))
H24: =IF($B24="","",SUMIFS('AHSP - Komponen'!$G$8:$G$87,'AHSP - Komponen'!$A$8:$A$87,B24)) | I24: =IF($B24="","",IF(E24="Manual",F24,H24*(1+G24)))
H25: =IF($B25="","",SUMIFS('AHSP - Komponen'!$G$8:$G$87,'AHSP - Komponen'!$A$8:$A$87,B25)) | I25: =IF($B25="","",IF(E25="Manual",F25,H25*(1+G25)))
H26: =IF($B26="","",SUMIFS('AHSP - Komponen'!$G$8:$G$87,'AHSP - Komponen'!$A$8:$A$87,B26)) | I26: =IF($B26="","",IF(E26="Manual",F26,H26*(1+G26)))
H27: =IF($B27="","",SUMIFS('AHSP - Komponen'!$G$8:$G$87,'AHSP - Komponen'!$A$8:$A$87,B27)) | I27: =IF($B27="","",IF(E27="Manual",F27,H27*(1+G27)))
H28: =IF($B28="","",SUMIFS('AHSP - Komponen'!$G$8:$G$87,'AHSP - Komponen'!$A$8:$A$87,B28)) | I28: =IF($B28="","",IF(E28="Manual",F28,H28*(1+G28)))
H29: =IF($B29="","",SUMIFS('AHSP - Komponen'!$G$8:$G$87,'AHSP - Komponen'!$A$8:$A$87,B29)) | I29: =IF($B29="","",IF(E29="Manual",F29,H29*(1+G29)))
H30: =IF($B30="","",SUMIFS('AHSP - Komponen'!$G$8:$G$87,'AHSP - Komponen'!$A$8:$A$87,B30)) | I30: =IF($B30="","",IF(E30="Manual",F30,H30*(1+G30)))
H31: =IF($B31="","",SUMIFS('AHSP - Komponen'!$G$8:$G$87,'AHSP - Komponen'!$A$8:$A$87,B31)) | I31: =IF($B31="","",IF(E31="Manual",F31,H31*(1+G31)))
H32: =IF($B32="","",SUMIFS('AHSP - Komponen'!$G$8:$G$87,'AHSP - Komponen'!$A$8:$A$87,B32)) | I32: =IF($B32="","",IF(E32="Manual",F32,H32*(1+G32)))
H33: =IF($B33="","",SUMIFS('AHSP - Komponen'!$G$8:$G$87,'AHSP - Komponen'!$A$8:$A$87,B33)) | I33: =IF($B33="","",IF(E33="Manual",F33,H33*(1+G33)))
H34: =IF($B34="","",SUMIFS('AHSP - Komponen'!$G$8:$G$87,'AHSP - Komponen'!$A$8:$A$87,B34)) | I34: =IF($B34="","",IF(E34="Manual",F34,H34*(1+G34)))
... H43: =IF($B43="","",SUMIFS('AHSP - Komponen'!$G$8:$G$87,'AHSP - Komponen'!$A$8:$A$87,B43)) | I43: =IF($B43="","",IF(E43="Manual",F43,H43*(1+G43)))

Sheet AHSP - Komponen
A1: AHSP - Rincian Komponen
A2: Rincian bahan/upah/alat untuk item AHSP bermode 'Detail'. Subtotal per Kode otomatis dijumlahkan ke sheet AHSP.
A7: Kode AHSP | B7: Jenis | C7: Uraian | D7: Satuan | E7: Koefisien | F7: Harga Satuan | G7: Jumlah
A8: SIP-01 | B8: Bahan | C8: Bata Merah | D8: bh | E8: 70 | F8: 700 | G8: =IF($A8="","",E8*F8) -> 49000
A9: SIP-01 | B9: Bahan | C9: Semen PC | D9: kg | E9: 9.68 | F9: 1700 | G9: =IF($A9="","",E9*F9) -> 16456
A10: SIP-01 | B10: Bahan | C10: Pasir Pasang | D10: m3 | E10: 0.045 | F10: 250000 | G10: =IF($A10="","",E10*F10) -> 11250
A11: SIP-01 | B11: Upah | C11: Tukang Batu | D11: OH | E11: 0.3 | F11: 120000 | G11: =IF($A11="","",E11*F11) -> 36000
A12: SIP-01 | B12: Upah | C12: Pekerja | D12: OH | E12: 0.6 | F12: 100000 | G12: =IF($A12="","",E12*F12) -> 60000
A13: SIP-02 | B13: Bahan | C13: Semen PC | D13: kg | E13: 5.18 | F13: 1700 | G13: =IF($A13="","",E13*F13) -> 8806
A14: SIP-02 | B14: Bahan | C14: Pasir Pasang | D14: m3 | E14: 0.023 | F14: 250000 | G14: =IF($A14="","",E14*F14) -> 5750
A15: SIP-02 | B15: Upah | C15: Tukang Batu | D15: OH | E15: 0.2 | F15: 120000 | G15: =IF($A15="","",E15*F15) -> 24000
A16: SIP-02 | B16: Upah | C16: Pekerja | D16: OH | E16: 0.25 | F16: 100000 | G16: =IF($A16="","",E16*F16) -> 25000
A17: INT-01 | B17: Bahan | C17: Gypsum Board 9mm | D17: lembar | E17: 0.35 | F17: 75000 | G17: =IF($A17="","",E17*F17) -> 26250
A18: INT-01 | B18: Bahan | C18: Hollow 4x4 | D18: m1 | E18: 1.2 | F18: 18000 | G18: =IF($A18="","",E18*F18) -> 21600
A19: INT-01 | B19: Upah | C19: Tukang | D19: OH | E19: 0.25 | F19: 120000 | G19: =IF($A19="","",E19*F19) -> 30000
... A24: BJ-01 | B24: Upah | C24: Pekerja | D24: OH | E24: 0.03 | F24: 100000 | G24: =IF($A24="","",E24*F24) -> 3000
G25: =IF($A25="","",E25*F25)
G26: =IF($A26="","",E26*F26)
G27: =IF($A27="","",E27*F27)
G28: =IF($A28="","",E28*F28)
G29: =IF($A29="","",E29*F29)
G30: =IF($A30="","",E30*F30)
G31: =IF($A31="","",E31*F31)
G32: =IF($A32="","",E32*F32)
G33: =IF($A33="","",E33*F33)
G34: =IF($A34="","",E34*F34)
G35: =IF($A35="","",E35*F35)
G36: =IF($A36="","",E36*F36)
... G87: =IF($A87="","",E87*F87)

Sheet RAB
A1: RAB — Rencana Anggaran Biaya
A2: Satu baris = satu dokumen RAB. Isi item pekerjaannya di sheet 'RAB - Item' (Nama Proyek harus sama persis).
A3: Nama Proyek | B3: Klien | C3: Lokasi | D3: Kategori | E3: Tanggal | F3: Subtotal | G3: PPN % | H3: Nilai PPN | I3: PPh % | J3: Nilai PPh | K3: Biaya Lain | L3: Total RAB
F4: =IF($A4="","",SUMIFS('RAB - Item'!$F$8:$F$157,'RAB - Item'!$A$8:$A$157,A4)) | H4: =IF($A4="","",F4*G4) | J4: =IF($A4="","",F4*I4) | L4: =IF($A4="","",F4+H4+J4+K4)
F5: =IF($A5="","",SUMIFS('RAB - Item'!$F$8:$F$157,'RAB - Item'!$A$8:$A$157,A5)) | H5: =IF($A5="","",F5*G5) | J5: =IF($A5="","",F5*I5) | L5: =IF($A5="","",F5+H5+J5+K5)
F6: =IF($A6="","",SUMIFS('RAB - Item'!$F$8:$F$157,'RAB - Item'!$A$8:$A$157,A6)) | H6: =IF($A6="","",F6*G6) | J6: =IF($A6="","",F6*I6) | L6: =IF($A6="","",F6+H6+J6+K6)
F7: =IF($A7="","",SUMIFS('RAB - Item'!$F$8:$F$157,'RAB - Item'!$A$8:$A$157,A7)) | H7: =IF($A7="","",F7*G7) | J7: =IF($A7="","",F7*I7) | L7: =IF($A7="","",F7+H7+J7+K7)
F8: =IF($A8="","",SUMIFS('RAB - Item'!$F$8:$F$157,'RAB - Item'!$A$8:$A$157,A8)) | H8: =IF($A8="","",F8*G8) | J8: =IF($A8="","",F8*I8) | L8: =IF($A8="","",F8+H8+J8+K8)
F9: =IF($A9="","",SUMIFS('RAB - Item'!$F$8:$F$157,'RAB - Item'!$A$8:$A$157,A9)) | H9: =IF($A9="","",F9*G9) | J9: =IF($A9="","",F9*I9) | L9: =IF($A9="","",F9+H9+J9+K9)
F10: =IF($A10="","",SUMIFS('RAB - Item'!$F$8:$F$157,'RAB - Item'!$A$8:$A$157,A10)) | H10: =IF($A10="","",F10*G10) | J10: =IF($A10="","",F10*I10) | L10: =IF($A10="","",F10+H10+J10+K10)
F11: =IF($A11="","",SUMIFS('RAB - Item'!$F$8:$F$157,'RAB - Item'!$A$8:$A$157,A11)) | H11: =IF($A11="","",F11*G11) | J11: =IF($A11="","",F11*I11) | L11: =IF($A11="","",F11+H11+J11+K11)
F12: =IF($A12="","",SUMIFS('RAB - Item'!$F$8:$F$157,'RAB - Item'!$A$8:$A$157,A12)) | H12: =IF($A12="","",F12*G12) | J12: =IF($A12="","",F12*I12) | L12: =IF($A12="","",F12+H12+J12+K12)
F13: =IF($A13="","",SUMIFS('RAB - Item'!$F$8:$F$157,'RAB - Item'!$A$8:$A$157,A13)) | H13: =IF($A13="","",F13*G13) | J13: =IF($A13="","",F13*I13) | L13: =IF($A13="","",F13+H13+J13+K13)
F14: =IF($A14="","",SUMIFS('RAB - Item'!$F$8:$F$157,'RAB - Item'!$A$8:$A$157,A14)) | H14: =IF($A14="","",F14*G14) | J14: =IF($A14="","",F14*I14) | L14: =IF($A14="","",F14+H14+J14+K14)
F15: =IF($A15="","",SUMIFS('RAB - Item'!$F$8:$F$157,'RAB - Item'!$A$8:$A$157,A15)) | H15: =IF($A15="","",F15*G15) | J15: =IF($A15="","",F15*I15) | L15: =IF($A15="","",F15+H15+J15+K15)
... F33: =IF($A33="","",SUMIFS('RAB - Item'!$F$8:$F$157,'RAB - Item'!$A$8:$A$157,A33)) | H33: =IF($A33="","",F33*G33) | J33: =IF($A33="","",F33*I33) | L33: =IF($A33="","",F33+H33+J33+K33)

Sheet RAB - Item
A1: RAB - Item Pekerjaan
A2: Nama Proyek harus sama persis dengan sheet RAB. Isi 'Kode AHSP' untuk melihat harga referensi dari AHSP (kolom bantu, tidak otomatis menimpa Harga Satuan).
A7: Nama Proyek | B7: Uraian Pekerjaan | C7: Satuan | D7: Volume | E7: Harga Satuan | F7: Jumlah | G7: Kode AHSP (opsional) | H7: Harga dari AHSP
F8: =IF($A8="","",D8*E8) | H8: =IF($G8="","",IFERROR(INDEX(AHSP!$I$4:$I$43,MATCH(G8,AHSP!$B$4:$B$43,0)),""))
F9: =IF($A9="","",D9*E9) | H9: =IF($G9="","",IFERROR(INDEX(AHSP!$I$4:$I$43,MATCH(G9,AHSP!$B$4:$B$43,0)),""))
F10: =IF($A10="","",D10*E10) | H10: =IF($G10="","",IFERROR(INDEX(AHSP!$I$4:$I$43,MATCH(G10,AHSP!$B$4:$B$43,0)),""))
F11: =IF($A11="","",D11*E11) | H11: =IF($G11="","",IFERROR(INDEX(AHSP!$I$4:$I$43,MATCH(G11,AHSP!$B$4:$B$43,0)),""))
F12: =IF($A12="","",D12*E12) | H12: =IF($G12="","",IFERROR(INDEX(AHSP!$I$4:$I$43,MATCH(G12,AHSP!$B$4:$B$43,0)),""))
F13: =IF($A13="","",D13*E13) | H13: =IF($G13="","",IFERROR(INDEX(AHSP!$I$4:$I$43,MATCH(G13,AHSP!$B$4:$B$43,0)),""))
F14: =IF($A14="","",D14*E14) | H14: =IF($G14="","",IFERROR(INDEX(AHSP!$I$4:$I$43,MATCH(G14,AHSP!$B$4:$B$43,0)),""))
F15: =IF($A15="","",D15*E15) | H15: =IF($G15="","",IFERROR(INDEX(AHSP!$I$4:$I$43,MATCH(G15,AHSP!$B$4:$B$43,0)),""))
F16: =IF($A16="","",D16*E16) | H16: =IF($G16="","",IFERROR(INDEX(AHSP!$I$4:$I$43,MATCH(G16,AHSP!$B$4:$B$43,0)),""))
F17: =IF($A17="","",D17*E17) | H17: =IF($G17="","",IFERROR(INDEX(AHSP!$I$4:$I$43,MATCH(G17,AHSP!$B$4:$B$43,0)),""))
F18: =IF($A18="","",D18*E18) | H18: =IF($G18="","",IFERROR(INDEX(AHSP!$I$4:$I$43,MATCH(G18,AHSP!$B$4:$B$43,0)),""))
F19: =IF($A19="","",D19*E19) | H19: =IF($G19="","",IFERROR(INDEX(AHSP!$I$4:$I$43,MATCH(G19,AHSP!$B$4:$B$43,0)),""))
... F157: =IF($A157="","",D157*E157) | H157: =IF($G157="","",IFERROR(INDEX(AHSP!$I$4:$I$43,MATCH(G157,AHSP!$B$4:$B$43,0)),""))

Sheet Penawaran Harga
A1: Penawaran Harga
A2: Satu baris = satu surat penawaran. Isi itemnya di sheet 'Penawaran - Item' (No Surat harus sama persis). Buka sheet 'Cetak Penawaran' untuk mencetak versi surat resmi.
A3: No Surat | B3: Tanggal | C3: Kepada Yth | D3: Alamat Klien | E3: Perihal | F3: Kategori | G3: Status | H3: Subtotal | I3: Diskon % | J3: Nilai Diskon | K3: PPN % | L3: Nilai PPN | M3: PPh % | N3: Nilai PPh | O3: Total Penawaran | P3: Syarat & Ketentuan | Q3: Kalimat Penutup | R3: Nama Penandatangan | S3: Jabatan Penandatangan
H4: =IF($A4="","",SUMIFS('Penawaran - Item'!$F$8:$F$157,'Penawaran - Item'!$A$8:$A$157,A4)) | J4: =IF($A4="","",H4*I4) | L4: =IF($A4="","",(H4-J4)*K4) | N4: =IF($A4="","",(H4-J4)*M4) | O4: =IF($A4="","",H4-J4+L4+N4) | R4: =IF($A4="","",OwnerName) | S4: =IF($A4="","",OwnerJabatan)
H5: =IF($A5="","",SUMIFS('Penawaran - Item'!$F$8:$F$157,'Penawaran - Item'!$A$8:$A$157,A5)) | J5: =IF($A5="","",H5*I5) | L5: =IF($A5="","",(H5-J5)*K5) | N5: =IF($A5="","",(H5-J5)*M5) | O5: =IF($A5="","",H5-J5+L5+N5) | R5: =IF($A5="","",OwnerName) | S5: =IF($A5="","",OwnerJabatan)
H6: =IF($A6="","",SUMIFS('Penawaran - Item'!$F$8:$F$157,'Penawaran - Item'!$A$8:$A$157,A6)) | J6: =IF($A6="","",H6*I6) | L6: =IF($A6="","",(H6-J6)*K6) | N6: =IF($A6="","",(H6-J6)*M6) | O6: =IF($A6="","",H6-J6+L6+N6) | R6: =IF($A6="","",OwnerName) | S6: =IF($A6="","",OwnerJabatan)
H7: =IF($A7="","",SUMIFS('Penawaran - Item'!$F$8:$F$157,'Penawaran - Item'!$A$8:$A$157,A7)) | J7: =IF($A7="","",H7*I7) | L7: =IF($A7="","",(H7-J7)*K7) | N7: =IF($A7="","",(H7-J7)*M7) | O7: =IF($A7="","",H7-J7+L7+N7) | R7: =IF($A7="","",OwnerName) | S7: =IF($A7="","",OwnerJabatan)
H8: =IF($A8="","",SUMIFS('Penawaran - Item'!$F$8:$F$157,'Penawaran - Item'!$A$8:$A$157,A8)) | J8: =IF($A8="","",H8*I8) | L8: =IF($A8="","",(H8-J8)*K8) | N8: =IF($A8="","",(H8-J8)*M8) | O8: =IF($A8="","",H8-J8+L8+N8) | R8: =IF($A8="","",OwnerName) | S8: =IF($A8="","",OwnerJabatan)
H9: =IF($A9="","",SUMIFS('Penawaran - Item'!$F$8:$F$157,'Penawaran - Item'!$A$8:$A$157,A9)) | J9: =IF($A9="","",H9*I9) | L9: =IF($A9="","",(H9-J9)*K9) | N9: =IF($A9="","",(H9-J9)*M9) | O9: =IF($A9="","",H9-J9+L9+N9) | R9: =IF($A9="","",OwnerName) | S9: =IF($A9="","",OwnerJabatan)
H10: =IF($A10="","",SUMIFS('Penawaran - Item'!$F$8:$F$157,'Penawaran - Item'!$A$8:$A$157,A10)) | J10: =IF($A10="","",H10*I10) | L10: =IF($A10="","",(H10-J10)*K10) | N10: =IF($A10="","",(H10-J10)*M10) | O10: =IF($A10="","",H10-J10+L10+N10) | R10: =IF($A10="","",OwnerName) | S10: =IF($A10="","",OwnerJabatan)
H11: =IF($A11="","",SUMIFS('Penawaran - Item'!$F$8:$F$157,'Penawaran - Item'!$A$8:$A$157,A11)) | J11: =IF($A11="","",H11*I11) | L11: =IF($A11="","",(H11-J11)*K11) | N11: =IF($A11="","",(H11-J11)*M11) | O11: =IF($A11="","",H11-J11+L11+N11) | R11: =IF($A11="","",OwnerName) | S11: =IF($A11="","",OwnerJabatan)
H12: =IF($A12="","",SUMIFS('Penawaran - Item'!$F$8:$F$157,'Penawaran - Item'!$A$8:$A$157,A12)) | J12: =IF($A12="","",H12*I12) | L12: =IF($A12="","",(H12-J12)*K12) | N12: =IF($A12="","",(H12-J12)*M12) | O12: =IF($A12="","",H12-J12+L12+N12) | R12: =IF($A12="","",OwnerName) | S12: =IF($A12="","",OwnerJabatan)
H13: =IF($A13="","",SUMIFS('Penawaran - Item'!$F$8:$F$157,'Penawaran - Item'!$A$8:$A$157,A13)) | J13: =IF($A13="","",H13*I13) | L13: =IF($A13="","",(H13-J13)*K13) | N13: =IF($A13="","",(H13-J13)*M13) | O13: =IF($A13="","",H13-J13+L13+N13) | R13: =IF($A13="","",OwnerName) | S13: =IF($A13="","",OwnerJabatan)
H14: =IF($A14="","",SUMIFS('Penawaran - Item'!$F$8:$F$157,'Penawaran - Item'!$A$8:$A$157,A14)) | J14: =IF($A14="","",H14*I14) | L14: =IF($A14="","",(H14-J14)*K14) | N14: =IF($A14="","",(H14-J14)*M14) | O14: =IF($A14="","",H14-J14+L14+N14) | R14: =IF($A14="","",OwnerName) | S14: =IF($A14="","",OwnerJabatan)
H15: =IF($A15="","",SUMIFS('Penawaran - Item'!$F$8:$F$157,'Penawaran - Item'!$A$8:$A$157,A15)) | J15: =IF($A15="","",H15*I15) | L15: =IF($A15="","",(H15-J15)*K15) | N15: =IF($A15="","",(H15-J15)*M15) | O15: =IF($A15="","",H15-J15+L15+N15) | R15: =IF($A15="","",OwnerName) | S15: =IF($A15="","",OwnerJabatan)
... H33: =IF($A33="","",SUMIFS('Penawaran - Item'!$F$8:$F$157,'Penawaran - Item'!$A$8:$A$157,A33)) | J33: =IF($A33="","",H33*I33) | L33: =IF($A33="","",(H33-J33)*K33) | N33: =IF($A33="","",(H33-J33)*M33) | O33: =IF($A33="","",H33-J33+L33+N33) | R33: =IF($A33="","",OwnerName) | S33: =IF($A33="","",OwnerJabatan)

Sheet Penawaran - Item
A1: Penawaran - Item Pekerjaan
A2: No Surat harus sama persis dengan sheet Penawaran Harga. Kolom 'Kunci' dipakai otomatis oleh sheet Cetak Penawaran, jangan diubah.
A7: No Surat | B7: Uraian Pekerjaan | C7: Satuan | D7: Volume | E7: Harga Satuan | F7: Jumlah | G7: Kode AHSP (opsional) | H7: Harga dari AHSP | I7: Kunci
F8: =IF($A8="","",D8*E8) | H8: =IF($G8="","",IFERROR(INDEX(AHSP!$I$4:$I$43,MATCH(G8,AHSP!$B$4:$B$43,0)),"")) | I8: =IF($A8="","",A8&"|"&COUNTIF($A$8:A8,A8))
F9: =IF($A9="","",D9*E9) | H9: =IF($G9="","",IFERROR(INDEX(AHSP!$I$4:$I$43,MATCH(G9,AHSP!$B$4:$B$43,0)),"")) | I9: =IF($A9="","",A9&"|"&COUNTIF($A$8:A9,A9))
F10: =IF($A10="","",D10*E10) | H10: =IF($G10="","",IFERROR(INDEX(AHSP!$I$4:$I$43,MATCH(G10,AHSP!$B$4:$B$43,0)),"")) | I10: =IF($A10="","",A10&"|"&COUNTIF($A$8:A10,A10))
F11: =IF($A11="","",D11*E11) | H11: =IF($G11="","",IFERROR(INDEX(AHSP!$I$4:$I$43,MATCH(G11,AHSP!$B$4:$B$43,0)),"")) | I11: =IF($A11="","",A11&"|"&COUNTIF($A$8:A11,A11))
F12: =IF($A12="","",D12*E12) | H12: =IF($G12="","",IFERROR(INDEX(AHSP!$I$4:$I$43,MATCH(G12,AHSP!$B$4:$B$43,0)),"")) | I12: =IF($A12="","",A12&"|"&COUNTIF($A$8:A12,A12))
F13: =IF($A13="","",D13*E13) | H13: =IF($G13="","",IFERROR(INDEX(AHSP!$I$4:$I$43,MATCH(G13,AHSP!$B$4:$B$43,0)),"")) | I13: =IF($A13="","",A13&"|"&COUNTIF($A$8:A13,A13))
F14: =IF($A14="","",D14*E14) | H14: =IF($G14="","",IFERROR(INDEX(AHSP!$I$4:$I$43,MATCH(G14,AHSP!$B$4:$B$43,0)),"")) | I14: =IF($A14="","",A14&"|"&COUNTIF($A$8:A14,A14))
F15: =IF($A15="","",D15*E15) | H15: =IF($G15="","",IFERROR(INDEX(AHSP!$I$4:$I$43,MATCH(G15,AHSP!$B$4:$B$43,0)),"")) | I15: =IF($A15="","",A15&"|"&COUNTIF($A$8:A15,A15))
F16: =IF($A16="","",D16*E16) | H16: =IF($G16="","",IFERROR(INDEX(AHSP!$I$4:$I$43,MATCH(G16,AHSP!$B$4:$B$43,0)),"")) | I16: =IF($A16="","",A16&"|"&COUNTIF($A$8:A16,A16))
F17: =IF($A17="","",D17*E17) | H17: =IF($G17="","",IFERROR(INDEX(AHSP!$I$4:$I$43,MATCH(G17,AHSP!$B$4:$B$43,0)),"")) | I17: =IF($A17="","",A17&"|"&COUNTIF($A$8:A17,A17))
F18: =IF($A18="","",D18*E18) | H18: =IF($G18="","",IFERROR(INDEX(AHSP!$I$4:$I$43,MATCH(G18,AHSP!$B$4:$B$43,0)),"")) | I18: =IF($A18="","",A18&"|"&COUNTIF($A$8:A18,A18))
F19: =IF($A19="","",D19*E19) | H19: =IF($G19="","",IFERROR(INDEX(AHSP!$I$4:$I$43,MATCH(G19,AHSP!$B$4:$B$43,0)),"")) | I19: =IF($A19="","",A19&"|"&COUNTIF($A$8:A19,A19))
... F157: =IF($A157="","",D157*E157) | H157: =IF($G157="","",IFERROR(INDEX(AHSP!$I$4:$I$43,MATCH(G157,AHSP!$B$4:$B$43,0)),"")) | I157: =IF($A157="","",A157&"|"&COUNTIF($A$8:A157,A157))

Sheet Cetak Penawaran
B2: Pilih No Surat:
A5: =CompanyName -> CV Mitra Creative
A6: =CompanyAddress&" - "&CompanyPhone -> Jl. Taman Asri No. 15, Pedurungan Tengah, Semarang - 0895811220203
A8: SURAT PENAWARAN HARGA
A10: No Surat | B10: =IF($C$2="","",IFERROR(INDEX('Penawaran Harga'!$A$4:$A$33,MATCH($C$2,'Penawaran Harga'!$A$4:$A$33,0)),""))
A11: Tanggal | B11: =IF($C$2="","",IFERROR(INDEX('Penawaran Harga'!$B$4:$B$33,MATCH($C$2,'Penawaran Harga'!$A$4:$A$33,0)),""))
A12: Kepada Yth | B12: =IF($C$2="","",IFERROR(INDEX('Penawaran Harga'!$C$4:$C$33,MATCH($C$2,'Penawaran Harga'!$A$4:$A$33,0)),""))
A13: Alamat | B13: =IF($C$2="","",IFERROR(INDEX('Penawaran Harga'!$D$4:$D$33,MATCH($C$2,'Penawaran Harga'!$A$4:$A$33,0)),""))
